Workbook

Sheet README
A1: Pokémon Emerald Imperium — Phase 4 Valuation
A3: Parse date | B3: 2026-09-01
A4: Run settings | B4: NORMAL difficulty; Minimal Grinding Mode OFF; level caps enforced; standard playthrough, no breeding (RUN_CONFIG.md)
A5: Damage engine | B5: RadicalRedShowdown/damage-calc @ 7f35400, @smogon/calc/adaptable, driven by a custom Imperium data layer
A6: Level cap ladder | B6: MEASURED from Boss_Battles.xlsx!Main rows 9-27, supplied 2026-09-01. Supersedes the earlier reconstruction, which was right on 18 of 19 caps (cp09 was interpolated at 53; it is 56).
A7: Generation pinned | B7: 9 — Inferred. Evidence: Tera Blast/Ivy Cudgel/Armor Cannon present; all 18 types carry both physical and special moves (per-move split)
A8: Engine verification | B8: 14/14 damage calcs match an independent hand implementation of the formula. Discrepancy rate 0.0%
A10: Source files | B10: rows
A11: 01_species.tsv (Phase 1) | B11: 1534
A12: 02_world.tsv (Phase 2) | B12: 419
A13: 03_trainers.tsv (Phase 3) | B13: 164
A14: 03_trainer_slots.tsv (Phase 3) | B14: 678
A15: imperium_layer.json | B15: 1,534 species / 937 moves / 18-type chart / 327 abilities
A17: Rows scored | B17: 42,026 = 1,311 obtainable forms x 19 checkpoints x {floor, ceiling}
A18: Scoring errors | B18: 0
A20: DATA INTEGRITY LOG | B20: see the Integrity sheet
A21: Colour key | B21: BLUE = hardcoded input you may change | BLACK = formula | GREEN = link to another sheet | YELLOW = key assumption

Sheet Assumptions
A1: COMPOSITE VALUE WEIGHTS — change these and the whole workbook recalculates
A2: Component | B2: Weight | C2: Why this weight
A3: w_offense | B3: 0.26 | C3: Computed from actual damage rolls; the most load-bearing axis
A4: w_defense | B4: 0.15 | C4: Single-hit survival, also from damage rolls
A5: w_sustain | B5: 0.16 | C5: Sweep depth on one lifebar with recovery, screens and hazard chip, minus the same species with no kit. 0.24 for defensive roles
A6: w_speed | B6: 0.12 | C6: Roster outsped. 0.04 for defensive roles, which do not want the stat
A7: w_utility | B7: 0.1 | C7: Breadth of non-damage tools; a cheaper measure, weighted lower
A8: w_typing | B8: 0.11 | C8: Resistance profile against THIS boss's actual attacking types
A9: w_niche | B9: 0.1 | C9: Best archetype fit, so a good specialist is not flattened by averaging
A10: SUM (must be 1.00) | B10: =SUM(B3:B9) -> 1
A11: w_sustain (defensive roles) | B11: 0.24 | C11: Walls, clerics, hazard setters and removers, pivots, tanks, trappers, status spreaders and screen setters use this instead of B5
A12: w_speed (defensive roles) | B12: 0.04 | C12: A wall paying 0.12 on a stat it does not want was a 12-point penalty for doing its job
A13: defensive SUM (must be 1.00) | B13: =B3+B4+B11+B12+B7+B8+B9 -> 1
A15: TIER THRESHOLDS on mean VORP (ceiling)
A16: Tier | B16: Min VORP | C16: Note
A17: S+ | B17: 0.274
A18: S | B18: 0.2085
A19: A | B19: 0.1538
A20: B | B20: 0.0991
A21: C | B21: 0.0555
A22: D | B22: -0.0102
A23: F | B23: -99
C24: Not curve-forced. If the hack genuinely has many S-tier options, that is the finding.
A26: INVESTMENT COST COMPONENTS
A27: Component | B27: Charge | C27: Why
A28: Non-neutral nature | B28: 1 | C28: Mint or breeding needed
A29: Held item required | B29: 1 | C29: Ceiling uses an item Phase 2 gates
A30: Ability differs from common | B30: 1 | C30: Ability Capsule / Patch
A31: Species needs an evolution item | B31: 1 | C31: From availability_basis
A32: Per gated TM used (cap 2.0) | B32: 0.5 | C32: TM competition and cost
A33: Any egg move used | B33: 2 | C33: RUN_CONFIG says breeding is NOT used in this run, so an egg-move ceiling is out of reach, not free
A34: Floor | B34: 0.5 | C34: So ROI never divides by zero
A36: EXCLUDED from cost | C36: EV-training time and breeding, per RUN_CONFIG: the eight unconfirmable fields were dropped in Phase 1. ROI here is therefore NOT comparable to a version of this analysis with a full cost model.

Sheet Checkpoints
A1: checkpoint | B1: checkpoint_label | C1: level_cap | D1: cap_basis | E1: roster_basis | F1: n_anchors | G1: n_roster_slots | H1: pool_size | I1: tms_available | J1: items_available | K1: anchor_trainers | M1: cap > previous?
A2: 1 | B2: 01_Pre-Roxanne | C2: 15 | D2: measured | E2: anchor_fight | F2: 1 | G2: 4 | H2: 423 | I2: 3 | J2: 1 | K2: Hoenn Leaders:ROXANNE:1
A3: 2 | B3: 02_Pre-Rustboro-Rival | C3: 20 | D3: measured | E3: anchor_fight | F3: 1 | G3: 30 | H3: 556 | I3: 7 | J3: 1 | K3: Rivals:DAWN:16 | M3: =IF(C3>C2,"ok","NOT MONOTONIC") -> ok
A4: 3 | B4: 03_Pre-Brawly | C4: 25 | D4: measured | E4: anchor_fight | F4: 1 | G4: 5 | H4: 705 | I4: 17 | J4: 1 | K4: Hoenn Leaders:BRAWLY:13 | M4: =IF(C4>C3,"ok","NOT MONOTONIC") -> ok
A5: 4 | B5: 04_Pre-Aqua-Museum | C5: 30 | D5: measured | E5: anchor_fight | F5: 2 | G5: 5 | H5: 869 | I5: 20 | J5: 1 | K5: Team Aqua:BACK TO BACK:24;Team Aqua:GRUNT1:24 | M5: =IF(C5>C4,"ok","NOT MONOTONIC") -> ok
A6: 5 | B6: 05_Pre-Route110-Rival | C6: 32 | D6: measured | E6: anchor_fight | F6: 1 | G6: 4 | H6: 883 | I6: 38 | J6: 1 | K6: Rivals:WALLY:99 | M6: =IF(C6>C5,"ok","NOT MONOTONIC") -> ok
A7: 6 | B7: 06_Pre-Wattson | C7: 34 | D7: measured | E7: anchor_fight | F7: 1 | G7: 5 | H7: 964 | I7: 74 | J7: 3 | K7: Hoenn Leaders:WATTSON:26 | M7: =IF(C7>C6,"ok","NOT MONOTONIC") -> ok
A8: 7 | B8: 07_Pre-MtChimney-Magma | C8: 44 | D8: measured | E8: anchor_fight | F8: 1 | G8: 6 | H8: 1211 | I8: 90 | J8: 7 | K8: Team Magma:MAXIE:25 | M8: =IF(C8>C7,"ok","NOT MONOTONIC") -> ok
A9: 8 | B9: 08_Pre-Flannery | C9: 47 | D9: measured | E9: anchor_fight | F9: 1 | G9: 6 | H9: 1221 | I9: 101 | J9: 7 | K9: Hoenn Leaders:FLANNERY:39 | M9: =IF(C9>C8,"ok","NOT MONOTONIC") -> ok
A10: 9 | B10: 09_Pre-TrickHouse | C10: 56 | D10: measured | E10: trick_house_sheet_substituted | F10: 0 | G10: 46 | H10: 1257 | I10: 135 | J10: 7 | K10: NONE | M10: =IF(C10>C9,"ok","NOT MONOTONIC") -> ok
A11: 10 | B11: 10_Pre-Norman | C11: 59 | D11: measured | E11: anchor_fight | F11: 1 | G11: 6 | H11: 1259 | I11: 135 | J11: 7 | K11: Hoenn Leaders:NORMAN:51 | M11: =IF(C11>C10,"ok","NOT MONOTONIC") -> ok
A12: 11 | B12: 11_Pre-Route119-Rival | C12: 64 | D12: measured | E12: anchor_fight | F12: 2 | G12: 6 | H12: 1266 | I12: 145 | J12: 8 | K12: Team Aqua:GRUNT 2:37;Team Aqua:ADMIN MATT:37 | M12: =IF(C12>C11,"ok","NOT MONOTONIC") -> ok
A13: 12 | B13: 12_Pre-Winona | C13: 68 | D13: measured | E13: anchor_fight | F13: 1 | G13: 6 | H13: 1272 | I13: 149 | J13: 11 | K13: Hoenn Leaders:WINONA:63 | M13: =IF(C13>C12,"ok","NOT MONOTONIC") -> ok
A14: 13 | B14: 13_Pre-Dawn-Lilycove | C14: 71 | D14: measured | E14: anchor_fight | F14: 1 | G14: 6 | H14: 1302 | I14: 157 | J14: 13 | K14: Rivals:DAWN:171 | M14: =IF(C14>C13,"ok","NOT MONOTONIC") -> ok
... A20: 19 | B20: 19_Pre-Champion | C20: 85 | D20: measured | E20: anchor_fight | F20: 7 | G20: 36 | H20: 1311 | I20: 174 | J20: 14 | K20: Elite 4:ELITE FOUR SIDNEY:13;Elite 4:ELITE FOUR PHOEBE:38;Elite 4:ELITE FOUR GLACIA:63;Elite 4:ELITE FOUR DRAKE:1;Elite 4:ELITE FOUR CYNTHIA:88;Elite 4:CHAMPION WALLACE:101;Elite 4:CHAMPION STEVEN:101 | M20: =IF(C20>C19,"ok","NOT MONOTONIC") -> ok
A22: All 19 caps are MEASURED from Boss_Battles.xlsx!Main. The anchor_trainers column names the fight each checkpoint is scored against; cp09 Pre-Trick House has no single boss, so its threat pool is the 46 Trick House sheet slots.

Sheet Valuation
A1: Species form | B1: BST | C1: Tier (formula) | D1: Primary niche | E1: First cp | F1: Stat S | G1: Tool T | H1: Type Y | I1: Niche fit | J1: Floor value | K1: Ceiling value | L1: Invest cost | M1: VORP (formula) | N1: ROI (formula) | O1: # cps | P1: Can't miss | Q1: Confidence | R1: Offense | S1: Defense | T1: Speed (ceiling) | U1: Utility | V1: Typing | W1: Replacement | X1: Sustain (kit) | Y1: Niche fit (mean) | Z1: Composite (formula) | AA1: Def role?
A2: Toxapex | B2: 495 | C2: =IF(M2>=Assumptions!$B$17,"S+",IF(M2>=Assumptions!$B$18,"S",IF(M2>=Assumptions!$B$19,"A",IF(M2>=Assumptions!$B$20,"B",IF(M2>=Assumptions!$B$21,"C",IF(M2>=Assumptions!$B$22,"D","F")))))) -> S+ | D2: mixed_wall | E2: 7 | F2: 0.8394 | G2: 0.76 | H2: 0.5476 | I2: 0.7291 | J2: 0.4417 | K2: 0.6938 | L2: 5 | M2: =Z2-W2 -> 0.354956 | N2: =IFERROR((Z2-J2)/L2,"") -> 0.0504312 | O2: 13 | P2: =FALSE() -> FALSE | Q2: Inferred | R2: 0.7194 | S2: 0.6414 | T2: 0.068 | U2: 0.4556 | V2: 0.5126 | W2: 0.3389 | X2: 0.9744 | Y2: 0.7208 | Z2: =Assumptions!$B$3*R2+Assumptions!$B$4*S2+IF(AA2=1,Assumptions!$B$11,Assumptions!$B$5)*X2+IF(AA2=1,Assumptions!$B$12,Assumptions!$B$6)*T2+Assumptions!$B$7*U2+Assumptions!$B$8*V2+Assumptions!$B$9*Y2 -> 0.693856 | AA2: 1
A3: Orbeetle-Mega | B3: 595 | C3: =IF(M3>=Assumptions!$B$17,"S+",IF(M3>=Assumptions!$B$18,"S",IF(M3>=Assumptions!$B$19,"A",IF(M3>=Assumptions!$B$20,"B",IF(M3>=Assumptions!$B$21,"C",IF(M3>=Assumptions!$B$22,"D","F")))))) -> S+ | D3: mixed_wall | E3: 7 | F3: 0.7418 | G3: 0.76 | H3: 0.4077 | I3: 0.6668 | J3: 0.4052 | K3: 0.6593 | L3: 4 | M3: =Z3-W3 -> 0.32046 | N3: =IFERROR((Z3-J3)/L3,"") -> 0.06354 | O3: 13 | P3: =FALSE() -> FALSE | Q3: Inferred | R3: 0.7507 | S3: 0.6622 | T3: 0.2661 | U3: 0.4497 | V3: 0.4322 | W3: 0.3389 | X3: 0.8098 | Y3: 0.6734 | Z3: =Assumptions!$B$3*R3+Assumptions!$B$4*S3+IF(AA3=1,Assumptions!$B$11,Assumptions!$B$5)*X3+IF(AA3=1,Assumptions!$B$12,Assumptions!$B$6)*T3+Assumptions!$B$7*U3+Assumptions!$B$8*V3+Assumptions!$B$9*Y3 -> 0.65936 | AA3: 1
A4: Ho-Oh | B4: 680 | C4: =IF(M4>=Assumptions!$B$17,"S+",IF(M4>=Assumptions!$B$18,"S",IF(M4>=Assumptions!$B$19,"A",IF(M4>=Assumptions!$B$20,"B",IF(M4>=Assumptions!$B$21,"C",IF(M4>=Assumptions!$B$22,"D","F")))))) -> S+ | D4: hazard_remover | E4: 13 | F4: 0.7714 | G4: 0.85 | H4: 0.5188 | I4: 0.768 | J4: 0.5428 | K4: 0.7227 | L4: 5 | M4: =Z4-W4 -> 0.295434 | N4: =IFERROR((Z4-J4)/L4,"") -> 0.0359868 | O4: 7 | P4: =TRUE() -> TRUE | Q4: Inferred | R4: 0.8231 | S4: 0.7044 | T4: 0.123 | U4: 0.5385 | V4: 0.4622 | W4: 0.4273 | X4: 0.9074 | Y4: 0.7568 | Z4: =Assumptions!$B$3*R4+Assumptions!$B$4*S4+IF(AA4=1,Assumptions!$B$11,Assumptions!$B$5)*X4+IF(AA4=1,Assumptions!$B$12,Assumptions!$B$6)*T4+Assumptions!$B$7*U4+Assumptions!$B$8*V4+Assumptions!$B$9*Y4 -> 0.722734 | AA4: 1
A5: Bronzong | B5: 500 | C5: =IF(M5>=Assumptions!$B$17,"S+",IF(M5>=Assumptions!$B$18,"S",IF(M5>=Assumptions!$B$19,"A",IF(M5>=Assumptions!$B$20,"B",IF(M5>=Assumptions!$B$21,"C",IF(M5>=Assumptions!$B$22,"D","F")))))) -> S+ | D5: trapper | E5: 6 | F5: 0.83 | G5: 0.6 | H5: 0.75 | I5: 0.6714 | J5: 0.3731 | K5: 0.7195 | L5: 4 | M5: =Z5-W5 -> 0.295122 | N5: =IFERROR((Z5-J5)/L5,"") -> 0.0866055 | O5: 14 | P5: =FALSE() -> FALSE | Q5: Inferred | R5: 0.7916 | S5: 0.6978 | T5: 0.0455 | U5: 0.5604 | V5: 0.5174 | W5: 0.4244 | X5: 0.9623 | Y5: 0.6331 | Z5: =Assumptions!$B$3*R5+Assumptions!$B$4*S5+IF(AA5=1,Assumptions!$B$11,Assumptions!$B$5)*X5+IF(AA5=1,Assumptions!$B$12,Assumptions!$B$6)*T5+Assumptions!$B$7*U5+Assumptions!$B$8*V5+Assumptions!$B$9*Y5 -> 0.719522 | AA5: 1
A6: Uxie | B6: 580 | C6: =IF(M6>=Assumptions!$B$17,"S+",IF(M6>=Assumptions!$B$18,"S",IF(M6>=Assumptions!$B$19,"A",IF(M6>=Assumptions!$B$20,"B",IF(M6>=Assumptions!$B$21,"C",IF(M6>=Assumptions!$B$22,"D","F")))))) -> S+ | D6: status_spreader | E6: 13 | F6: 0.8758 | G6: 0.6 | H6: 0.75 | I6: 0.6796 | J6: 0.4075 | K6: 0.7182 | L6: 4 | M6: =Z6-W6 -> 0.29132 | N6: =IFERROR((Z6-J6)/L6,"") -> 0.07768 | O6: 7 | P6: =TRUE() -> TRUE | Q6: Inferred | R6: 0.7758 | S6: 0.7231 | T6: 0.254 | U6: 0.5385 | V6: 0.4923 | W6: 0.4269 | X6: 0.9246 | Y6: 0.6798 | Z6: =Assumptions!$B$3*R6+Assumptions!$B$4*S6+IF(AA6=1,Assumptions!$B$11,Assumptions!$B$5)*X6+IF(AA6=1,Assumptions!$B$12,Assumptions!$B$6)*T6+Assumptions!$B$7*U6+Assumptions!$B$8*V6+Assumptions!$B$9*Y6 -> 0.71822 | AA6: 1
A7: Zekrom | B7: 680 | C7: =IF(M7>=Assumptions!$B$17,"S+",IF(M7>=Assumptions!$B$18,"S",IF(M7>=Assumptions!$B$19,"A",IF(M7>=Assumptions!$B$20,"B",IF(M7>=Assumptions!$B$21,"C",IF(M7>=Assumptions!$B$22,"D","F")))))) -> S+ | D7: weather_terrain_setter | E7: 13 | F7: 0.7434 | G7: 0.6 | H7: 0.75 | I7: 0.6515 | J7: 0.4092 | K7: 0.6958 | L7: 4 | M7: =Z7-W7 -> 0.284623 | N7: =IFERROR((Z7-J7)/L7,"") -> 0.07165575 | O7: 7 | P7: =TRUE() -> TRUE | Q7: Inferred | R7: 0.9686 | S7: 0.6095 | T7: 0.3016 | U7: 0.6923 | V7: 0.498 | W7: 0.4112 | X7: 0.795 | Y7: 0.6516 | Z7: =Assumptions!$B$3*R7+Assumptions!$B$4*S7+IF(AA7=1,Assumptions!$B$11,Assumptions!$B$5)*X7+IF(AA7=1,Assumptions!$B$12,Assumptions!$B$6)*T7+Assumptions!$B$7*U7+Assumptions!$B$8*V7+Assumptions!$B$9*Y7 -> 0.695823 | AA7: 0
A8: Mesprit | B8: 580 | C8: =IF(M8>=Assumptions!$B$17,"S+",IF(M8>=Assumptions!$B$18,"S",IF(M8>=Assumptions!$B$19,"A",IF(M8>=Assumptions!$B$20,"B",IF(M8>=Assumptions!$B$21,"C",IF(M8>=Assumptions!$B$22,"D","F")))))) -> S+ | D8: status_spreader | E8: 13 | F8: 0.596 | G8: 0.6 | H8: 0.75 | I8: 0.6293 | J8: 0.3921 | K8: 0.7106 | L8: 4 | M8: =Z8-W8 -> 0.283676 | N8: =IFERROR((Z8-J8)/L8,"") -> 0.079619 | O8: 7 | P8: =TRUE() -> TRUE | Q8: Inferred | R8: 0.7842 | S8: 0.6569 | T8: 0.1429 | U8: 0.6154 | V8: 0.4923 | W8: 0.4269 | X8: 0.9325 | Y8: 0.6294 | Z8: =Assumptions!$B$3*R8+Assumptions!$B$4*S8+IF(AA8=1,Assumptions!$B$11,Assumptions!$B$5)*X8+IF(AA8=1,Assumptions!$B$12,Assumptions!$B$6)*T8+Assumptions!$B$7*U8+Assumptions!$B$8*V8+Assumptions!$B$9*Y8 -> 0.710576 | AA8: 1
A9: Glalie-Mega | B9: 580 | C9: =IF(M9>=Assumptions!$B$17,"S+",IF(M9>=Assumptions!$B$18,"S",IF(M9>=Assumptions!$B$19,"A",IF(M9>=Assumptions!$B$20,"B",IF(M9>=Assumptions!$B$21,"C",IF(M9>=Assumptions!$B$22,"D","F")))))) -> S+ | D9: suicide_lead | E9: 7 | F9: 0.7431 | G9: 0.6 | H9: 0.75 | I9: 0.6586 | J9: 0.3646 | K9: 0.6229 | L9: 4 | M9: =Z9-W9 -> 0.28019 | N9: =IFERROR((Z9-J9)/L9,"") -> 0.0645725 | O9: 13 | P9: =FALSE() -> FALSE | Q9: Inferred | R9: 0.9375 | S9: 0.4691 | T9: 0.2661 | U9: 0.5326 | V9: 0.3755 | W9: 0.3427 | X9: 0.7273 | Y9: 0.6591 | Z9: =Assumptions!$B$3*R9+Assumptions!$B$4*S9+IF(AA9=1,Assumptions!$B$11,Assumptions!$B$5)*X9+IF(AA9=1,Assumptions!$B$12,Assumptions!$B$6)*T9+Assumptions!$B$7*U9+Assumptions!$B$8*V9+Assumptions!$B$9*Y9 -> 0.62289 | AA9: 0
A10: Audino-Mega | B10: 545 | C10: =IF(M10>=Assumptions!$B$17,"S+",IF(M10>=Assumptions!$B$18,"S",IF(M10>=Assumptions!$B$19,"A",IF(M10>=Assumptions!$B$20,"B",IF(M10>=Assumptions!$B$21,"C",IF(M10>=Assumptions!$B$22,"D","F")))))) -> S+ | D10: cleric | E10: 7 | F10: 0.9481 | G10: 1 | H10: 0.5278 | I10: 0.8952 | J10: 0.5229 | K10: 0.7783 | L10: 6 | M10: =Z10-W10 -> 0.279831 | N10: =IFERROR((Z10-J10)/L10,"") -> 0.042571833 | O10: 13 | P10: =FALSE() -> FALSE | Q10: Inferred | R10: 0.8063 | S10: 0.7884 | T10: 0.1115 | U10: 0.645 | V10: 0.5253 | W10: 0.4985 | X10: 0.9815 | Y10: 0.8813 | Z10: =Assumptions!$B$3*R10+Assumptions!$B$4*S10+IF(AA10=1,Assumptions!$B$11,Assumptions!$B$5)*X10+IF(AA10=1,Assumptions!$B$12,Assumptions!$B$6)*T10+Assumptions!$B$7*U10+Assumptions!$B$8*V10+Assumptions!$B$9*Y10 -> 0.778331 | AA10: 1
A11: Ting-Lu | B11: 570 | C11: =IF(M11>=Assumptions!$B$17,"S+",IF(M11>=Assumptions!$B$18,"S",IF(M11>=Assumptions!$B$19,"A",IF(M11>=Assumptions!$B$20,"B",IF(M11>=Assumptions!$B$21,"C",IF(M11>=Assumptions!$B$22,"D","F")))))) -> S | D11: trapper | E11: 7 | F11: 0.893 | G11: 0.6 | H11: 0.75 | I11: 0.6827 | J11: 0.4006 | K11: 0.6785 | L11: 4 | M11: =Z11-W11 -> 0.272744 | N11: =IFERROR((Z11-J11)/L11,"") -> 0.069486 | O11: 13 | P11: =FALSE() -> FALSE | Q11: Inferred | R11: 0.7642 | S11: 0.778 | T11: 0.0618 | U11: 0.4556 | V11: 0.4394 | W11: 0.4058 | X11: 0.8269 | Y11: 0.6833 | Z11: =Assumptions!$B$3*R11+Assumptions!$B$4*S11+IF(AA11=1,Assumptions!$B$11,Assumptions!$B$5)*X11+IF(AA11=1,Assumptions!$B$12,Assumptions!$B$6)*T11+Assumptions!$B$7*U11+Assumptions!$B$8*V11+Assumptions!$B$9*Y11 -> 0.678544 | AA11: 1
A12: Lugia | B12: 680 | C12: =IF(M12>=Assumptions!$B$17,"S+",IF(M12>=Assumptions!$B$18,"S",IF(M12>=Assumptions!$B$19,"A",IF(M12>=Assumptions!$B$20,"B",IF(M12>=Assumptions!$B$21,"C",IF(M12>=Assumptions!$B$22,"D","F")))))) -> S | D12: special_wall | E12: 13 | F12: 0.9471 | G12: 0.64 | H12: 0.4692 | I12: 0.6833 | J12: 0.4255 | K12: 0.7291 | L12: 5 | M12: =Z12-W12 -> 0.265911 | N12: =IFERROR((Z12-J12)/L12,"") -> 0.0607222 | O12: 7 | P12: =TRUE() -> TRUE | Q12: Inferred | R12: 0.814 | S12: 0.9949 | T12: 0.4524 | U12: 0.5385 | V12: 0.4728 | W12: 0.4632 | X12: 0.7328 | Y12: 0.6841 | Z12: =Assumptions!$B$3*R12+Assumptions!$B$4*S12+IF(AA12=1,Assumptions!$B$11,Assumptions!$B$5)*X12+IF(AA12=1,Assumptions!$B$12,Assumptions!$B$6)*T12+Assumptions!$B$7*U12+Assumptions!$B$8*V12+Assumptions!$B$9*Y12 -> 0.729111 | AA12: 1
A13: Tapu Fini-Tapu-Fini | B13: 570 | C13: =IF(M13>=Assumptions!$B$17,"S+",IF(M13>=Assumptions!$B$18,"S",IF(M13>=Assumptions!$B$19,"A",IF(M13>=Assumptions!$B$20,"B",IF(M13>=Assumptions!$B$21,"C",IF(M13>=Assumptions!$B$22,"D","F")))))) -> S | D13: hazard_remover | E13: 13 | F13: 0.805 | G13: 0.6 | H13: 0.5972 | I13: 0.6404 | J13: 0.3859 | K13: 0.6771 | L13: 4 | M13: =Z13-W13 -> 0.26174 | N13: =IFERROR((Z13-J13)/L13,"") -> 0.072785 | O13: 7 | P13: =TRUE() -> TRUE | Q13: Inferred | R13: 0.8321 | S13: 0.7057 | T13: 0.1984 | U13: 0.6923 | V13: 0.5527 | W13: 0.4153 | X13: 0.8584 | Y13: 0.6366 | Z13: =Assumptions!$B$3*R13+Assumptions!$B$4*S13+IF(AA13=1,Assumptions!$B$11,Assumptions!$B$5)*X13+IF(AA13=1,Assumptions!$B$12,Assumptions!$B$6)*T13+Assumptions!$B$7*U13+Assumptions!$B$8*V13+Assumptions!$B$9*Y13 -> 0.67704 | AA13: 0
A14: Archaludon | B14: 600 | C14: =IF(M14>=Assumptions!$B$17,"S+",IF(M14>=Assumptions!$B$18,"S",IF(M14>=Assumptions!$B$19,"A",IF(M14>=Assumptions!$B$20,"B",IF(M14>=Assumptions!$B$21,"C",IF(M14>=Assumptions!$B$22,"D","F")))))) -> S | D14: hazard_setter | E14: 9 | F14: 0.7476 | G14: 0.85 | H14: 0.75 | I14: 0.8116 | J14: 0.4028 | K14: 0.7239 | L14: 4 | M14: =Z14-W14 -> 0.261515 | N14: =IFERROR((Z14-J14)/L14,"") -> 0.08027875 | O14: 11 | P14: =FALSE() -> FALSE | Q14: Inferred | R14: 0.8709 | S14: 0.679 | T14: 0.1924 | U14: 0.3566 | V14: 0.5593 | W14: 0.4624 | X14: 0.9023 | Y14: 0.742 | Z14: =Assumptions!$B$3*R14+Assumptions!$B$4*S14+IF(AA14=1,Assumptions!$B$11,Assumptions!$B$5)*X14+IF(AA14=1,Assumptions!$B$12,Assumptions!$B$6)*T14+Assumptions!$B$7*U14+Assumptions!$B$8*V14+Assumptions!$B$9*Y14 -> 0.723915 | AA14: 1
A15: Volbeat | B15: 482 | C15: =IF(M15>=Assumptions!$B$17,"S+",IF(M15>=Assumptions!$B$18,"S",IF(M15>=Assumptions!$B$19,"A",IF(M15>=Assumptions!$B$20,"B",IF(M15>=Assumptions!$B$21,"C",IF(M15>=Assumptions!$B$22,"D","F")))))) -> S | D15: speed_control | E15: 2 | F15: 0.8128 | G15: 0.85 | H15: 0.75 | I15: 0.8244 | J15: 0.4693 | K15: 0.6591 | L15: 5.83 | M15: =Z15-W15 -> 0.260342 | N15: =IFERROR((Z15-J15)/L15,"") -> 0.03256295 | O15: 18 | P15: =FALSE() -> FALSE | Q15: Inferred | R15: 0.7236 | S15: 0.639 | T15: 0.4972 | U15: 0.5897 | V15: 0.509 | W15: 0.3988 | X15: 0.7372 | Y15: 0.8258 | Z15: =Assumptions!$B$3*R15+Assumptions!$B$4*S15+IF(AA15=1,Assumptions!$B$11,Assumptions!$B$5)*X15+IF(AA15=1,Assumptions!$B$12,Assumptions!$B$6)*T15+Assumptions!$B$7*U15+Assumptions!$B$8*V15+Assumptions!$B$9*Y15 -> 0.659142 | AA15: 0
A16: Aerodactyl-Mega | B16: 615 | C16: =IF(M16>=Assumptions!$B$17,"S+",IF(M16>=Assumptions!$B$18,"S",IF(M16>=Assumptions!$B$19,"A",IF(M16>=Assumptions!$B$20,"B",IF(M16>=Assumptions!$B$21,"C",IF(M16>=Assumptions!$B$22,"D","F")))))) -> S | D16: physical_sweeper | E16: 7 | F16: 0.9704 | G16: 0.4 | H16: 0.75 | I16: 0.6868 | J16: 0.4258 | K16: 0.7338 | L16: 6 | M16: =Z16-W16 -> 0.256898 | N16: =IFERROR((Z16-J16)/L16,"") -> 0.051333 | O16: 13 | P16: =FALSE() -> FALSE | Q16: Inferred | R16: 0.8962 | S16: 0.5394 | T16: 0.8624 | U16: 0.574 | V16: 0.4748 | W16: 0.4769 | X16: 0.8625 | Y16: 0.6876 | Z16: =Assumptions!$B$3*R16+Assumptions!$B$4*S16+IF(AA16=1,Assumptions!$B$11,Assumptions!$B$5)*X16+IF(AA16=1,Assumptions!$B$12,Assumptions!$B$6)*T16+Assumptions!$B$7*U16+Assumptions!$B$8*V16+Assumptions!$B$9*Y16 -> 0.733798 | AA16: 0
A17: Cresselia | B17: 600 | C17: =IF(M17>=Assumptions!$B$17,"S+",IF(M17>=Assumptions!$B$18,"S",IF(M17>=Assumptions!$B$19,"A",IF(M17>=Assumptions!$B$20,"B",IF(M17>=Assumptions!$B$21,"C",IF(M17>=Assumptions!$B$22,"D","F")))))) -> S | D17: weather_terrain_setter | E17: 9 | F17: 0.9133 | G17: 0.45 | H17: 0.75 | I17: 0.5795 | J17: 0.477 | K17: 0.711 | L17: 4 | M17: =Z17-W17 -> 0.25653 | N17: =IFERROR((Z17-J17)/L17,"") -> 0.0584825 | O17: 11 | P17: =TRUE() -> TRUE | Q17: Inferred | R17: 0.7976 | S17: 0.8181 | T17: 0.2497 | U17: 0.4335 | V17: 0.4787 | W17: 0.4544 | X17: 0.9071 | Y17: 0.5714 | Z17: =Assumptions!$B$3*R17+Assumptions!$B$4*S17+IF(AA17=1,Assumptions!$B$11,Assumptions!$B$5)*X17+IF(AA17=1,Assumptions!$B$12,Assumptions!$B$6)*T17+Assumptions!$B$7*U17+Assumptions!$B$8*V17+Assumptions!$B$9*Y17 -> 0.71093 | AA17: 1
A18: Gallade-Mega | B18: 618 | C18: =IF(M18>=Assumptions!$B$17,"S+",IF(M18>=Assumptions!$B$18,"S",IF(M18>=Assumptions!$B$19,"A",IF(M18>=Assumptions!$B$20,"B",IF(M18>=Assumptions!$B$21,"C",IF(M18>=Assumptions!$B$22,"D","F")))))) -> S | D18: physical_sweeper | E18: 7 | F18: 0.9484 | G18: 1 | H18: 0.75 | I18: 0.9304 | J18: 0.4351 | K18: 0.7331 | L18: 4 | M18: =Z18-W18 -> 0.256164 | N18: =IFERROR((Z18-J18)/L18,"") -> 0.074491 | O18: 13 | P18: =FALSE() -> FALSE | Q18: Inferred | R18: 0.9685 | S18: 0.6137 | T18: 0.422 | U18: 0.5799 | V18: 0.4771 | W18: 0.4769 | X18: 0.8438 | Y18: 0.9308 | Z18: =Assumptions!$B$3*R18+Assumptions!$B$4*S18+IF(AA18=1,Assumptions!$B$11,Assumptions!$B$5)*X18+IF(AA18=1,Assumptions!$B$12,Assumptions!$B$6)*T18+Assumptions!$B$7*U18+Assumptions!$B$8*V18+Assumptions!$B$9*Y18 -> 0.733064 | AA18: 0
A19: Suicune | B19: 580 | C19: =IF(M19>=Assumptions!$B$17,"S+",IF(M19>=Assumptions!$B$18,"S",IF(M19>=Assumptions!$B$19,"A",IF(M19>=Assumptions!$B$20,"B",IF(M19>=Assumptions!$B$21,"C",IF(M19>=Assumptions!$B$22,"D","F")))))) -> S | D19: weather_terrain_setter | E19: 9 | F19: 0.8469 | G19: 0.45 | H19: 0.75 | I19: 0.5695 | J19: 0.3732 | K19: 0.6514 | L19: 4 | M19: =Z19-W19 -> 0.253904 | N19: =IFERROR((Z19-J19)/L19,"") -> 0.069551 | O19: 11 | P19: =TRUE() -> TRUE | Q19: Inferred | R19: 0.8025 | S19: 0.7048 | T19: 0.285 | U19: 0.3846 | V19: 0.4998 | W19: 0.3975 | X19: 0.9526 | Y19: 0.5698 | Z19: =Assumptions!$B$3*R19+Assumptions!$B$4*S19+IF(AA19=1,Assumptions!$B$11,Assumptions!$B$5)*X19+IF(AA19=1,Assumptions!$B$12,Assumptions!$B$6)*T19+Assumptions!$B$7*U19+Assumptions!$B$8*V19+Assumptions!$B$9*Y19 -> 0.651404 | AA19: 0
A20: Shuckle | B20: 505 | C20: =IF(M20>=Assumptions!$B$17,"S+",IF(M20>=Assumptions!$B$18,"S",IF(M20>=Assumptions!$B$19,"A",IF(M20>=Assumptions!$B$20,"B",IF(M20>=Assumptions!$B$21,"C",IF(M20>=Assumptions!$B$22,"D","F")))))) -> S | D20: hazard_setter | E20: 2 | F20: 0.4454 | G20: 0.85 | H20: 0.75 | I20: 0.7572 | J20: 0.3613 | K20: 0.6942 | L20: 6.83 | M20: =Z20-W20 -> 0.246424 | N20: =IFERROR((Z20-J20)/L20,"") -> 0.048729722 | O20: 18 | P20: =FALSE() -> FALSE | Q20: Inferred | R20: 0.7255 | S20: 0.9009 | T20: 0 | U20: 0.312 | V20: 0.4445 | W20: 0.4477 | X20: 0.9191 | Y20: 0.6968 | Z20: =Assumptions!$B$3*R20+Assumptions!$B$4*S20+IF(AA20=1,Assumptions!$B$11,Assumptions!$B$5)*X20+IF(AA20=1,Assumptions!$B$12,Assumptions!$B$6)*T20+Assumptions!$B$7*U20+Assumptions!$B$8*V20+Assumptions!$B$9*Y20 -> 0.694124 | AA20: 1
A21: Tapu Koko-Tapu-Koko | B21: 570 | C21: =IF(M21>=Assumptions!$B$17,"S+",IF(M21>=Assumptions!$B$18,"S",IF(M21>=Assumptions!$B$19,"A",IF(M21>=Assumptions!$B$20,"B",IF(M21>=Assumptions!$B$21,"C",IF(M21>=Assumptions!$B$22,"D","F")))))) -> S | D21: physical_sweeper | E21: 13 | F21: 0.9134 | G21: 0.6 | H21: 0.75 | I21: 0.7491 | J21: 0.4304 | K21: 0.7119 | L21: 4 | M21: =Z21-W21 -> 0.243842 | N21: =IFERROR((Z21-J21)/L21,"") -> 0.0703605 | O21: 7 | P21: =TRUE() -> TRUE | Q21: Inferred | R21: 0.9028 | S21: 0.4497 | T21: 0.6905 | U21: 0.7692 | V21: 0.5553 | W21: 0.468 | X21: 0.7116 | Y21: 0.7494 | Z21: =Assumptions!$B$3*R21+Assumptions!$B$4*S21+IF(AA21=1,Assumptions!$B$11,Assumptions!$B$5)*X21+IF(AA21=1,Assumptions!$B$12,Assumptions!$B$6)*T21+Assumptions!$B$7*U21+Assumptions!$B$8*V21+Assumptions!$B$9*Y21 -> 0.711842 | AA21: 0
A22: Mew | B22: 600 | C22: =IF(M22>=Assumptions!$B$17,"S+",IF(M22>=Assumptions!$B$18,"S",IF(M22>=Assumptions!$B$19,"A",IF(M22>=Assumptions!$B$20,"B",IF(M22>=Assumptions!$B$21,"C",IF(M22>=Assumptions!$B$22,"D","F")))))) -> S | D22: special_sweeper | E22: 9 | F22: 0.6992 | G22: 0.6 | H22: 0.75 | I22: 0.6677 | J22: 0.3341 | K22: 0.7288 | L22: 4 | M22: =Z22-W22 -> 0.24265 | N22: =IFERROR((Z22-J22)/L22,"") -> 0.0986625 | O22: 11 | P22: =TRUE() -> TRUE | Q22: Inferred | R22: 0.945 | S22: 0.6459 | T22: 0.3923 | U22: 0.7692 | V22: 0.4787 | W22: 0.4861 | X22: 0.8912 | Y22: 0.6692 | Z22: =Assumptions!$B$3*R22+Assumptions!$B$4*S22+IF(AA22=1,Assumptions!$B$11,Assumptions!$B$5)*X22+IF(AA22=1,Assumptions!$B$12,Assumptions!$B$6)*T22+Assumptions!$B$7*U22+Assumptions!$B$8*V22+Assumptions!$B$9*Y22 -> 0.72875 | AA22: 0
A23: Mewtwo | B23: 680 | C23: =IF(M23>=Assumptions!$B$17,"S+",IF(M23>=Assumptions!$B$18,"S",IF(M23>=Assumptions!$B$19,"A",IF(M23>=Assumptions!$B$20,"B",IF(M23>=Assumptions!$B$21,"C",IF(M23>=Assumptions!$B$22,"D","F")))))) -> S | D23: special_sweeper | E23: 13 | F23: 0.9431 | G23: 0.4 | H23: 0.75 | I23: 0.6764 | J23: 0.439 | K23: 0.7254 | L23: 4 | M23: =Z23-W23 -> 0.241686 | N23: =IFERROR((Z23-J23)/L23,"") -> 0.0715965 | O23: 7 | P23: =TRUE() -> TRUE | Q23: Inferred | R23: 0.9313 | S23: 0.6095 | T23: 0.6587 | U23: 0.5385 | V23: 0.4923 | W23: 0.4837 | X23: 0.8571 | Y23: 0.6764 | Z23: =Assumptions!$B$3*R23+Assumptions!$B$4*S23+IF(AA23=1,Assumptions!$B$11,Assumptions!$B$5)*X23+IF(AA23=1,Assumptions!$B$12,Assumptions!$B$6)*T23+Assumptions!$B$7*U23+Assumptions!$B$8*V23+Assumptions!$B$9*Y23 -> 0.725386 | AA23: 0
A24: Slowking | B24: 490 | C24: =IF(M24>=Assumptions!$B$17,"S+",IF(M24>=Assumptions!$B$18,"S",IF(M24>=Assumptions!$B$19,"A",IF(M24>=Assumptions!$B$20,"B",IF(M24>=Assumptions!$B$21,"C",IF(M24>=Assumptions!$B$22,"D","F")))))) -> S | D24: bulky_pivot | E24: 1 | F24: 0.8326 | G24: 0.85 | H24: 0.5198 | I24: 0.7796 | J24: 0.4984 | K24: 0.7135 | L24: 4.68 | M24: =Z24-W24 -> 0.241061 | N24: =IFERROR((Z24-J24)/L24,"") -> 0.045953205 | O24: 19 | P24: =FALSE() -> FALSE | Q24: Unresolved | R24: 0.8124 | S24: 0.6604 | T24: 0.1121 | U24: 0.4899 | V24: 0.4627 | W24: 0.4724 | X24: 0.9234 | Y24: 0.7719 | Z24: =Assumptions!$B$3*R24+Assumptions!$B$4*S24+IF(AA24=1,Assumptions!$B$11,Assumptions!$B$5)*X24+IF(AA24=1,Assumptions!$B$12,Assumptions!$B$6)*T24+Assumptions!$B$7*U24+Assumptions!$B$8*V24+Assumptions!$B$9*Y24 -> 0.713461 | AA24: 1
A25: Regieleki | B25: 580 | C25: =IF(M25>=Assumptions!$B$17,"S+",IF(M25>=Assumptions!$B$18,"S",IF(M25>=Assumptions!$B$19,"A",IF(M25>=Assumptions!$B$20,"B",IF(M25>=Assumptions!$B$21,"C",IF(M25>=Assumptions!$B$22,"D","F")))))) -> S | D25: revenge_killer | E25: 13 | F25: 0.9073 | G25: 0.4 | H25: 0.75 | I25: 0.6222 | J25: 0.4947 | K25: 0.7018 | L25: 4 | M25: =Z25-W25 -> 0.240491 | N25: =IFERROR((Z25-J25)/L25,"") -> 0.05177275 | O25: 7 | P25: =TRUE() -> TRUE | Q25: Inferred | R25: 0.8881 | S25: 0.4152 | T25: 0.9722 | U25: 0.6154 | V25: 0.5127 | W25: 0.4613 | X25: 0.6984 | Y25: 0.6226 | Z25: =Assumptions!$B$3*R25+Assumptions!$B$4*S25+IF(AA25=1,Assumptions!$B$11,Assumptions!$B$5)*X25+IF(AA25=1,Assumptions!$B$12,Assumptions!$B$6)*T25+Assumptions!$B$7*U25+Assumptions!$B$8*V25+Assumptions!$B$9*Y25 -> 0.701791 | AA25: 0
A26: Clefable | B26: 483 | C26: =IF(M26>=Assumptions!$B$17,"S+",IF(M26>=Assumptions!$B$18,"S",IF(M26>=Assumptions!$B$19,"A",IF(M26>=Assumptions!$B$20,"B",IF(M26>=Assumptions!$B$21,"C",IF(M26>=Assumptions!$B$22,"D","F")))))) -> S | D26: special_wall | E26: 6 | F26: 0.8682 | G26: 0.88 | H26: 0.5298 | I26: 0.7891 | J26: 0.3321 | K26: 0.7261 | L26: 6 | M26: =Z26-W26 -> 0.238357 | N26: =IFERROR((Z26-J26)/L26,"") -> 0.065676167 | O26: 14 | P26: =FALSE() -> FALSE | Q26: Inferred | R26: 0.7557 | S26: 0.6939 | T26: 0.1069 | U26: 0.533 | V26: 0.534 | W26: 0.4878 | X26: 0.9701 | Y26: 0.7645 | Z26: =Assumptions!$B$3*R26+Assumptions!$B$4*S26+IF(AA26=1,Assumptions!$B$11,Assumptions!$B$5)*X26+IF(AA26=1,Assumptions!$B$12,Assumptions!$B$6)*T26+Assumptions!$B$7*U26+Assumptions!$B$8*V26+Assumptions!$B$9*Y26 -> 0.726157 | AA26: 1
A27: Regirock | B27: 580 | C27: =IF(M27>=Assumptions!$B$17,"S+",IF(M27>=Assumptions!$B$18,"S",IF(M27>=Assumptions!$B$19,"A",IF(M27>=Assumptions!$B$20,"B",IF(M27>=Assumptions!$B$21,"C",IF(M27>=Assumptions!$B$22,"D","F")))))) -> S | D27: physical_wall | E27: 13 | F27: 0.9818 | G27: 0.76 | H27: 0.3889 | I27: 0.7293 | J27: 0.3692 | K27: 0.6573 | L27: 5 | M27: =Z27-W27 -> 0.238098 | N27: =IFERROR((Z27-J27)/L27,"") -> 0.0576196 | O27: 7 | P27: =TRUE() -> TRUE | Q27: Inferred | R27: 0.7732 | S27: 0.7773 | T27: 0.0318 | U27: 0.4615 | V27: 0.3915 | W27: 0.4192 | X27: 0.7341 | Y27: 0.73 | Z27: =Assumptions!$B$3*R27+Assumptions!$B$4*S27+IF(AA27=1,Assumptions!$B$11,Assumptions!$B$5)*X27+IF(AA27=1,Assumptions!$B$12,Assumptions!$B$6)*T27+Assumptions!$B$7*U27+Assumptions!$B$8*V27+Assumptions!$B$9*Y27 -> 0.657298 | AA27: 1
A28: Registeel | B28: 580 | C28: =IF(M28>=Assumptions!$B$17,"S+",IF(M28>=Assumptions!$B$18,"S",IF(M28>=Assumptions!$B$19,"A",IF(M28>=Assumptions!$B$20,"B",IF(M28>=Assumptions!$B$21,"C",IF(M28>=Assumptions!$B$22,"D","F")))))) -> S | D28: tank | E28: 13 | F28: 0.8122 | G28: 0.45 | H28: 0.5198 | I28: 0.5907 | J28: 0.3829 | K28: 0.6366 | L28: 4 | M28: =Z28-W28 -> 0.238095 | N28: =IFERROR((Z28-J28)/L28,"") -> 0.06342375 | O28: 7 | P28: =TRUE() -> TRUE | Q28: Inferred | R28: 0.7684 | S28: 0.7473 | T28: 0.0437 | U28: 0.3846 | V28: 0.5242 | W28: 0.3985 | X28: 0.6984 | Y28: 0.5923 | Z28: =Assumptions!$B$3*R28+Assumptions!$B$4*S28+IF(AA28=1,Assumptions!$B$11,Assumptions!$B$5)*X28+IF(AA28=1,Assumptions!$B$12,Assumptions!$B$6)*T28+Assumptions!$B$7*U28+Assumptions!$B$8*V28+Assumptions!$B$9*Y28 -> 0.636595 | AA28: 1
A29: Jirachi | B29: 600 | C29: =IF(M29>=Assumptions!$B$17,"S+",IF(M29>=Assumptions!$B$18,"S",IF(M29>=Assumptions!$B$19,"A",IF(M29>=Assumptions!$B$20,"B",IF(M29>=Assumptions!$B$21,"C",IF(M29>=Assumptions!$B$22,"D","F")))))) -> S | D29: status_spreader | E29: 4 | F29: 0.7662 | G29: 0.6 | H29: 0.75 | I29: 0.6599 | J29: 0.4568 | K29: 0.6983 | L29: 3.94 | M29: =Z29-W29 -> 0.235734 | N29: =IFERROR((Z29-J29)/L29,"") -> 0.061303046 | O29: 16 | P29: =TRUE() -> TRUE | Q29: Inferred | R29: 0.7311 | S29: 0.7185 | T29: 0.3995 | U29: 0.5962 | V29: 0.5169 | W29: 0.4626 | X29: 0.8571 | Y29: 0.6231 | Z29: =Assumptions!$B$3*R29+Assumptions!$B$4*S29+IF(AA29=1,Assumptions!$B$11,Assumptions!$B$5)*X29+IF(AA29=1,Assumptions!$B$12,Assumptions!$B$6)*T29+Assumptions!$B$7*U29+Assumptions!$B$8*V29+Assumptions!$B$9*Y29 -> 0.698334 | AA29: 1
A30: Claydol | B30: 510 | C30: =IF(M30>=Assumptions!$B$17,"S+",IF(M30>=Assumptions!$B$18,"S",IF(M30>=Assumptions!$B$19,"A",IF(M30>=Assumptions!$B$20,"B",IF(M30>=Assumptions!$B$21,"C",IF(M30>=Assumptions!$B$22,"D","F")))))) -> S | D30: status_spreader | E30: 7 | F30: 0.7546 | G30: 0.6 | H30: 0.75 | I30: 0.6578 | J30: 0.4255 | K30: 0.6783 | L30: 4 | M30: =Z30-W30 -> 0.235256 | N30: =IFERROR((Z30-J30)/L30,"") -> 0.063214 | O30: 13 | P30: =FALSE() -> FALSE | Q30: Inferred | R30: 0.7165 | S30: 0.6196 | T30: 0.1243 | U30: 0.574 | V30: 0.4424 | W30: 0.4431 | X30: 0.938 | Y30: 0.6297 | Z30: =Assumptions!$B$3*R30+Assumptions!$B$4*S30+IF(AA30=1,Assumptions!$B$11,Assumptions!$B$5)*X30+IF(AA30=1,Assumptions!$B$12,Assumptions!$B$6)*T30+Assumptions!$B$7*U30+Assumptions!$B$8*V30+Assumptions!$B$9*Y30 -> 0.678356 | AA30: 1
A31: Aggron-Mega | B31: 630 | C31: =IF(M31>=Assumptions!$B$17,"S+",IF(M31>=Assumptions!$B$18,"S",IF(M31>=Assumptions!$B$19,"A",IF(M31>=Assumptions!$B$20,"B",IF(M31>=Assumptions!$B$21,"C",IF(M31>=Assumptions!$B$22,"D","F")))))) -> S | D31: physical_wall | E31: 7 | F31: 0.98 | G31: 0.76 | H31: 0.5198 | I31: 0.7616 | J31: 0.3884 | K31: 0.65 | L31: 4 | M31: =Z31-W31 -> 0.234897 | N31: =IFERROR((Z31-J31)/L31,"") -> 0.06539925 | O31: 13 | P31: =FALSE() -> FALSE | Q31: Inferred | R31: 0.8353 | S31: 0.7437 | T31: 0.0901 | U31: 0.3432 | V31: 0.5112 | W31: 0.4151 | X31: 0.6407 | Y31: 0.7334 | Z31: =Assumptions!$B$3*R31+Assumptions!$B$4*S31+IF(AA31=1,Assumptions!$B$11,Assumptions!$B$5)*X31+IF(AA31=1,Assumptions!$B$12,Assumptions!$B$6)*T31+Assumptions!$B$7*U31+Assumptions!$B$8*V31+Assumptions!$B$9*Y31 -> 0.649997 | AA31: 1
A32: Slowbro-Mega | B32: 590 | C32: =IF(M32>=Assumptions!$B$17,"S+",IF(M32>=Assumptions!$B$18,"S",IF(M32>=Assumptions!$B$19,"A",IF(M32>=Assumptions!$B$20,"B",IF(M32>=Assumptions!$B$21,"C",IF(M32>=Assumptions!$B$22,"D","F")))))) -> S | D32: bulky_pivot | E32: 7 | F32: 0.863 | G32: 0.85 | H32: 0.5198 | I32: 0.7872 | J32: 0.5191 | K32: 0.7276 | L32: 4 | M32: =Z32-W32 -> 0.233311 | N32: =IFERROR((Z32-J32)/L32,"") -> 0.05212775 | O32: 13 | P32: =FALSE() -> FALSE | Q32: Inferred | R32: 0.8794 | S32: 0.6709 | T32: 0.0516 | U32: 0.5326 | V32: 0.4738 | W32: 0.4943 | X32: 0.8875 | Y32: 0.7789 | Z32: =Assumptions!$B$3*R32+Assumptions!$B$4*S32+IF(AA32=1,Assumptions!$B$11,Assumptions!$B$5)*X32+IF(AA32=1,Assumptions!$B$12,Assumptions!$B$6)*T32+Assumptions!$B$7*U32+Assumptions!$B$8*V32+Assumptions!$B$9*Y32 -> 0.727611 | AA32: 1
A33: Overqwil | B33: 530 | C33: =IF(M33>=Assumptions!$B$17,"S+",IF(M33>=Assumptions!$B$18,"S",IF(M33>=Assumptions!$B$19,"A",IF(M33>=Assumptions!$B$20,"B",IF(M33>=Assumptions!$B$21,"C",IF(M33>=Assumptions!$B$22,"D","F")))))) -> S | D33: physical_wall | E33: 4 | F33: 0.832 | G33: 0.88 | H33: 0.5615 | I33: 0.7869 | J33: 0.4152 | K33: 0.6681 | L33: 4.88 | M33: =Z33-W33 -> 0.232414 | N33: =IFERROR((Z33-J33)/L33,"") -> 0.051826639 | O33: 16 | P33: =FALSE() -> FALSE | Q33: Inferred | R33: 0.8021 | S33: 0.7569 | T33: 0.3052 | U33: 0.423 | V33: 0.5487 | W33: 0.4357 | X33: 0.6487 | Y33: 0.7548 | Z33: =Assumptions!$B$3*R33+Assumptions!$B$4*S33+IF(AA33=1,Assumptions!$B$11,Assumptions!$B$5)*X33+IF(AA33=1,Assumptions!$B$12,Assumptions!$B$6)*T33+Assumptions!$B$7*U33+Assumptions!$B$8*V33+Assumptions!$B$9*Y33 -> 0.668114 | AA33: 1
A34: Audino | B34: 445 | C34: =IF(M34>=Assumptions!$B$17,"S+",IF(M34>=Assumptions!$B$18,"S",IF(M34>=Assumptions!$B$19,"A",IF(M34>=Assumptions!$B$20,"B",IF(M34>=Assumptions!$B$21,"C",IF(M34>=Assumptions!$B$22,"D","F")))))) -> S | D34: cleric | E34: 3 | F34: 0.8748 | G34: 1 | H34: 0.4762 | I34: 0.8702 | J34: 0.4269 | K34: 0.7252 | L34: 5.88 | M34: =Z34-W34 -> 0.23182 | N34: =IFERROR((Z34-J34)/L34,"") -> 0.050734694 | O34: 17 | P34: =FALSE() -> FALSE | Q34: Inferred | R34: 0.7276 | S34: 0.6852 | T34: 0.147 | U34: 0.6063 | V34: 0.4584 | W34: 0.4934 | X34: 0.969 | Y34: 0.8377 | Z34: =Assumptions!$B$3*R34+Assumptions!$B$4*S34+IF(AA34=1,Assumptions!$B$11,Assumptions!$B$5)*X34+IF(AA34=1,Assumptions!$B$12,Assumptions!$B$6)*T34+Assumptions!$B$7*U34+Assumptions!$B$8*V34+Assumptions!$B$9*Y34 -> 0.72522 | AA34: 1
A35: Tentacruel | B35: 530 | C35: =IF(M35>=Assumptions!$B$17,"S+",IF(M35>=Assumptions!$B$18,"S",IF(M35>=Assumptions!$B$19,"A",IF(M35>=Assumptions!$B$20,"B",IF(M35>=Assumptions!$B$21,"C",IF(M35>=Assumptions!$B$22,"D","F")))))) -> S | D35: status_spreader | E35: 2 | F35: 0.8281 | G35: 0.6 | H35: 0.75 | I35: 0.6711 | J35: 0.3925 | K35: 0.6659 | L35: 3.69 | M35: =Z35-W35 -> 0.23174 | N35: =IFERROR((Z35-J35)/L35,"") -> 0.074102981 | O35: 18 | P35: =FALSE() -> FALSE | Q35: Inferred | R35: 0.7381 | S35: 0.6758 | T35: 0.4829 | U35: 0.5855 | V35: 0.5152 | W35: 0.4342 | X35: 0.7284 | Y35: 0.6331 | Z35: =Assumptions!$B$3*R35+Assumptions!$B$4*S35+IF(AA35=1,Assumptions!$B$11,Assumptions!$B$5)*X35+IF(AA35=1,Assumptions!$B$12,Assumptions!$B$6)*T35+Assumptions!$B$7*U35+Assumptions!$B$8*V35+Assumptions!$B$9*Y35 -> 0.66594 | AA35: 1
A36: Forretress | B36: 465 | C36: =IF(M36>=Assumptions!$B$17,"S+",IF(M36>=Assumptions!$B$18,"S",IF(M36>=Assumptions!$B$19,"A",IF(M36>=Assumptions!$B$20,"B",IF(M36>=Assumptions!$B$21,"C",IF(M36>=Assumptions!$B$22,"D","F")))))) -> S | D36: hazard_setter | E36: 4 | F36: 0.7085 | G36: 0.85 | H36: 0.75 | I36: 0.8045 | J36: 0.4308 | K36: 0.6751 | L36: 3.94 | M36: =Z36-W36 -> 0.229246 | N36: =IFERROR((Z36-J36)/L36,"") -> 0.062016751 | O36: 16 | P36: =FALSE() -> FALSE | Q36: Inferred | R36: 0.8135 | S36: 0.6415 | T36: 0.0962 | U36: 0.6202 | V36: 0.5265 | W36: 0.4459 | X36: 0.6892 | Y36: 0.7822 | Z36: =Assumptions!$B$3*R36+Assumptions!$B$4*S36+IF(AA36=1,Assumptions!$B$11,Assumptions!$B$5)*X36+IF(AA36=1,Assumptions!$B$12,Assumptions!$B$6)*T36+Assumptions!$B$7*U36+Assumptions!$B$8*V36+Assumptions!$B$9*Y36 -> 0.675146 | AA36: 1
A37: Metagross-Mega | B37: 700 | C37: =IF(M37>=Assumptions!$B$17,"S+",IF(M37>=Assumptions!$B$18,"S",IF(M37>=Assumptions!$B$19,"A",IF(M37>=Assumptions!$B$20,"B",IF(M37>=Assumptions!$B$21,"C",IF(M37>=Assumptions!$B$22,"D","F")))))) -> S | D37: physical_wallbreaker | E37: 18 | F37: 0.8684 | G37: 0.6 | H37: 0.75 | I37: 0.7159 | J37: 0.4216 | K37: 0.7141 | L37: 4 | M37: =Z37-W37 -> 0.225588 | N37: =IFERROR((Z37-J37)/L37,"") -> 0.073122 | O37: 2 | P37: =FALSE() -> FALSE | Q37: Inferred | R37: 0.9284 | S37: 0.6862 | T37: 0.375 | U37: 0.5385 | V37: 0.546 | W37: 0.4885 | X37: 0.8704 | Y37: 0.716 | Z37: =Assumptions!$B$3*R37+Assumptions!$B$4*S37+IF(AA37=1,Assumptions!$B$11,Assumptions!$B$5)*X37+IF(AA37=1,Assumptions!$B$12,Assumptions!$B$6)*T37+Assumptions!$B$7*U37+Assumptions!$B$8*V37+Assumptions!$B$9*Y37 -> 0.714088 | AA37: 0
A38: Volcanion | B38: 600 | C38: =IF(M38>=Assumptions!$B$17,"S+",IF(M38>=Assumptions!$B$18,"S",IF(M38>=Assumptions!$B$19,"A",IF(M38>=Assumptions!$B$20,"B",IF(M38>=Assumptions!$B$21,"C",IF(M38>=Assumptions!$B$22,"D","F")))))) -> S | D38: hazard_remover | E38: 7 | F38: 0.6489 | G38: 0.85 | H38: 0.5427 | I38: 0.7483 | J38: 0.3999 | K38: 0.668 | L38: 4 | M38: =Z38-W38 -> 0.224605 | N38: =IFERROR((Z38-J38)/L38,"") -> 0.06702625 | O38: 13 | P38: =TRUE() -> TRUE | Q38: Inferred | R38: 0.8912 | S38: 0.7093 | T38: 0.1193 | U38: 0.3787 | V38: 0.4842 | W38: 0.4434 | X38: 0.6676 | Y38: 0.7377 | Z38: =Assumptions!$B$3*R38+Assumptions!$B$4*S38+IF(AA38=1,Assumptions!$B$11,Assumptions!$B$5)*X38+IF(AA38=1,Assumptions!$B$12,Assumptions!$B$6)*T38+Assumptions!$B$7*U38+Assumptions!$B$8*V38+Assumptions!$B$9*Y38 -> 0.668005 | AA38: 1
A39: Vaporeon | B39: 525 | C39: =IF(M39>=Assumptions!$B$17,"S+",IF(M39>=Assumptions!$B$18,"S",IF(M39>=Assumptions!$B$19,"A",IF(M39>=Assumptions!$B$20,"B",IF(M39>=Assumptions!$B$21,"C",IF(M39>=Assumptions!$B$22,"D","F")))))) -> S | D39: bulky_pivot | E39: 6 | F39: 0.7314 | G39: 0.85 | H39: 0.5476 | I39: 0.7599 | J39: 0.3594 | K39: 0.7128 | L39: 5 | M39: =Z39-W39 -> 0.222986 | N39: =IFERROR((Z39-J39)/L39,"") -> 0.0706772 | O39: 14 | P39: =FALSE() -> FALSE | Q39: Inferred | R39: 0.7524 | S39: 0.7045 | T39: 0.133 | U39: 0.5275 | V39: 0.4841 | W39: 0.4898 | X39: 0.9389 | Y39: 0.7483 | Z39: =Assumptions!$B$3*R39+Assumptions!$B$4*S39+IF(AA39=1,Assumptions!$B$11,Assumptions!$B$5)*X39+IF(AA39=1,Assumptions!$B$12,Assumptions!$B$6)*T39+Assumptions!$B$7*U39+Assumptions!$B$8*V39+Assumptions!$B$9*Y39 -> 0.712786 | AA39: 1
A40: Carbink | B40: 500 | C40: =IF(M40>=Assumptions!$B$17,"S+",IF(M40>=Assumptions!$B$18,"S",IF(M40>=Assumptions!$B$19,"A",IF(M40>=Assumptions!$B$20,"B",IF(M40>=Assumptions!$B$21,"C",IF(M40>=Assumptions!$B$22,"D","F")))))) -> S | D40: hazard_setter | E40: 4 | F40: 0.5282 | G40: 0.85 | H40: 0.75 | I40: 0.7721 | J40: 0.4397 | K40: 0.667 | L40: 3.88 | M40: =Z40-W40 -> 0.221094 | N40: =IFERROR((Z40-J40)/L40,"") -> 0.058580928 | O40: 16 | P40: =FALSE() -> FALSE | Q40: Inferred | R40: 0.7395 | S40: 0.6613 | T40: 0.1259 | U40: 0.423 | V40: 0.4407 | W40: 0.4459 | X40: 0.8534 | Y40: 0.749 | Z40: =Assumptions!$B$3*R40+Assumptions!$B$4*S40+IF(AA40=1,Assumptions!$B$11,Assumptions!$B$5)*X40+IF(AA40=1,Assumptions!$B$12,Assumptions!$B$6)*T40+Assumptions!$B$7*U40+Assumptions!$B$8*V40+Assumptions!$B$9*Y40 -> 0.666994 | AA40: 1
...

Sheet Validation
A1: phase | B1: check | C1: result | D1: severity | E1: affected | F1: effect
A2: 4 | B2: Checkpoint ladder monotonic, 15->85 | C2: 19 checkpoints, strictly increasing | D2: — | E2: 0 | F2: pass
A3: 4 | B3: Level cap ladder | C3: 19 of 19 MEASURED from Boss_Battles.xlsx!Main | D3: — | E3: 0 | F3: supersedes the reconstruction, which was right on 18 of 19
A4: 4 | B4: Reconstructed vs measured caps | C4: 18 of 19 exact; cp09 was 53, is 56 | D4: Material | E4: 1 | F4: cp09 pool 1255->1257; all cp09 scores re-run
A5: 4 | B5: Boss_Battles sheets vs Phase 3 parse | C5: 695 source Ability: lines vs 678 parsed slots | D5: — | E5: 0 | F5: the 17-row gap is exactly the 17 mega post-transformation ability lines, folded into mega_ability. Nothing missing
A6: 4 | B6: RUN_CONFIG anchor counts re-measured | C6: 695/45/9/576/39 all match exactly | D6: — | E6: 0 | F6: source file identical to what Phase 3 read
A7: 4 | B7: Battle_Rewards.xlsx vs 02_world | C7: 17 of 17 rows present with matching locations | D7: — | E7: 0 | F7: supersede claim was correct; reward_trainer column added
A8: 4 | B8: Checkpoints with no boss roster | C8: 1 (cp09 Pre-TrickHouse) | D8: Material | E8: 1 | F8: the checkpoint IS the Trick House, so its 46 sheet slots are the correct threat pool; downgraded from Unresolved
A9: 4 | B9: Damage engine vs independent hand implementation | C9: 14/14 exact match on rolls, stats and max HP | D9: — | E9: 0 | F9: discrepancy rate 0.0%
A10: 4 | B10: Scoring run errors | C10: 0 of 42,026 rows | D10: — | E10: 0 | F10: pass
A11: 4 | B11: BST correlation BEFORE rebalance (validation 1) | C11: floor 0.705 / ceiling 0.745 | D11: Material | E11: 0 | F11: FAILED the ~0.7 threshold; framework rebalanced
A12: 4 | B12: v2 SUSTAIN axis: raw sweep depth vs BST | C12: r=0.809 — REJECTED as a stat proxy | D12: Material | E12: 0 | F12: replaced by the kit delta (with-kit minus no-kit), r=0.463 at row level; zero for the 27% of rows with no sustain kit
A13: 4 | B13: v2: mean VORP vs BST, like-for-like | C13: v1 r=0.841 -> v2 r=0.785 | D13: — | E13: 0 | F13: moved the right way
... A28: 4 | B28: Tier robustness at the thresholds | C28: see tier_fragile column | D28: Material | E28: 0 | F28: Metagross-Mega, Crobat and Wyrdeer sit within 1.2e-4 of a tier edge; their tier flips between the two equally valid ways of averaging VORP and should not be read as settled

Sheet Integrity
B1: DATA INTEGRITY LOG — Phase 4
B3: CORRECTIONS TO MY OWN WORK (each would have silently poisoned results):
B4: 1. imperium_layer.json exports the Defense base stat as 'df' (the fork's internal compressed key). The public Specie interface requires 'def'. Unremapped, baseStats.def is undefined and every physical calc returns NaN rather than erroring. Remapped with a guard that throws.
B5: 2. layer['items'] is an ALPHABETICALLY SORTED name list, not an id-indexed array. Using items[param] for EVO_ITEM resolved id 211 to 'Fire Gem' instead of 'Fire Stone'. The authoritative source is 02_world.internal_id.
B6: 3. 02_world.internal_id is POLYMORPHIC BY entity_type: TM and HM rows store the MOVE id, not an item id. 28 ids collide with real items — 211 is Fire Stone as an item and Steel Wing as a TM. TM/HM rows excluded from the item map; all nine evolution stones then resolve correctly.
B7: 4. Species were joined layer<->TSV on species_name, which collapsed every alternate form onto its base ('Venusaur' base and 'Venusaur' Mega are two rows with one name) and silently dropped 510 of 1,534 movepools. internal_index is an exact 1:1 join across all 1,534 rows; switched.
B8: 5. An earlier draft asserted Imperium's move table had no healing field and fell back to a curated recovery name list. It DOES carry flags.healing (36 moves). Recovery gates three wall archetypes, so this mattered. The flag also marks DRAIN moves, which heal off damage dealt and must not qualify a wall; split into 15 reliable recovery and 13 drain.
B10: FRAMEWORK FAILURE AND REBALANCE:
B11: 6. primary_niche_fit vs BST came out r=0.745 (ceiling) / 0.705 (floor), ABOVE the ~0.7 threshold in archetypes.md — the scoring was a BST proxy. Two fixes: toolkit scoring restricted to role-relevant tools (breadth is itself a BST proxy), and a stat-SHAPE term blended in so a 480-BST species with 130 Atk reads as more sweeper-shaped than a flat 600. After: r=0.476 / 0.365.
B13: DATA GAPS CARRIED, NOT SMOOTHED:
B14: 7. RESOLVED. The level-cap ladder is now MEASURED from Boss_Battles.xlsx!Main, supplied after the first Phase 4 pass. The earlier reconstruction agreed on 18 of 19 caps; cp09 Pre-Trick House was interpolated at 53 and is actually 56. Checkpoint 19 is labelled Pre-Champion, not Pre-Elite4.
B15: 8. WHY THE LADDER WENT MISSING: the Phase 1/2 README declared Boss_Battles.xlsx superseded because its content appeared verbatim inside General_Documents___Locations.xlsx, on a check of 'content-row counts identical across all 11 boss sheets'. The workbook has TWELVE sheets. The twelfth is Main, and Main carries the ladder. A supersede check that enumerates only the sheets it already knows about cannot detect one it does not. The rule this changes: compare SHEET COUNTS before comparing row counts within sheets.
... B28: 18. Volbeat's 145-171% Bug Buzz on Lokix looked wrong and is correct: Imperium's Bug->Dark is 2.0 and the hand formula reproduces 132-156 exactly.

Sheet Charts
A1: Tier | B1: Species
A2: S+ | B2: 9
A3: S | B3: 39
A4: A | B4: 100
A5: B | B5: 190
A6: C | B6: 286
A7: D | B7: 268
A8: F | B8: 419
A11: Checkpoint | B11: Obtainable pool | C11: TMs available | D11: Level cap
A12: 1 | B12: 423 | C12: 3 | D12: 15
A13: 2 | B13: 556 | C13: 7 | D13: 20
A14: 3 | B14: 705 | C14: 17 | D14: 25
A15: 4 | B15: 869 | C15: 20 | D15: 30
A16: 5 | B16: 883 | C16: 38 | D16: 32
A17: 6 | B17: 964 | C17: 74 | D17: 34
A18: 7 | B18: 1211 | C18: 90 | D18: 44
A19: 8 | B19: 1221 | C19: 101 | D19: 47
A20: 9 | B20: 1257 | C20: 135 | D20: 56
A21: 10 | B21: 1259 | C21: 135 | D21: 59
A22: 11 | B22: 1266 | C22: 145 | D22: 64
A23: 12 | B23: 1272 | C23: 149 | D23: 68
... A30: 19 | B30: 1311 | C30: 174 | D30: 85
A34: BST | B34: primary_niche_fit
A35: 510 | B35: 0.8084
A36: 525 | B36: 0.5581
A37: 509 | B37: 0.7012
A38: 420 | B38: 0.6462
A39: 525 | B39: 0.7941
A40: 210 | B40: 0.5948
A41: 290 | B41: 0.607
A42: 460 | B42: 0.6881
A43: 341 | B43: 0.6383
A44: 314 | B44: 0.5716
A45: 270 | B45: 0.5072
A46: 534 | B46: 0.7257
... A434: 600 | B434: 0.7106
